2022-11-21 23:09:09,360 - app - ERROR - test error
2022-11-22 00:01:03,897 - app - ERROR - Exception on /profile/ [GET]
Traceback (most recent call last):
  File "/Users/liutianhao/Downloads/team_2_lll/venv/lib/python3.10/site-packages/flask/app.py", line 2525, in wsgi_app
    response = self.full_dispatch_request()
  File "/Users/liutianhao/Downloads/team_2_lll/venv/lib/python3.10/site-packages/flask/app.py", line 1822, in full_dispatch_request
    rv = self.handle_user_exception(e)
  File "/Users/liutianhao/Downloads/team_2_lll/venv/lib/python3.10/site-packages/flask/app.py", line 1820, in full_dispatch_request
    rv = self.dispatch_request()
  File "/Users/liutianhao/Downloads/team_2_lll/venv/lib/python3.10/site-packages/flask/app.py", line 1796, in dispatch_request
    return self.ensure_sync(self.view_functions[rule.endpoint])(**view_args)
  File "/Users/liutianhao/Downloads/team_2_lll/blueprint/profile_blueprint.py", line 37, in index
    return render_template('profile.html', user=user, form=form, shop=user.shop[3])
IndexError: list index out of range
2022-11-22 00:51:11,425 - app - ERROR - Exception on /profile/ [POST]
Traceback (most recent call last):
  File "/Users/liutianhao/Downloads/team_2_lll/venv/lib/python3.10/site-packages/flask/app.py", line 2525, in wsgi_app
    response = self.full_dispatch_request()
  File "/Users/liutianhao/Downloads/team_2_lll/venv/lib/python3.10/site-packages/flask/app.py", line 1822, in full_dispatch_request
    rv = self.handle_user_exception(e)
  File "/Users/liutianhao/Downloads/team_2_lll/venv/lib/python3.10/site-packages/flask/app.py", line 1820, in full_dispatch_request
    rv = self.dispatch_request()
  File "/Users/liutianhao/Downloads/team_2_lll/venv/lib/python3.10/site-packages/flask/app.py", line 1796, in dispatch_request
    return self.ensure_sync(self.view_functions[rule.endpoint])(**view_args)
  File "/Users/liutianhao/Downloads/team_2_lll/blueprint/profile_blueprint.py", line 48, in index
    print(price + " " + name + " " + description + " " + tag + " " + shop_id)
TypeError: unsupported operand type(s) for +: 'float' and 'str'
2022-11-22 00:54:19,387 - app - ERROR - Exception on /profile/ [POST]
Traceback (most recent call last):
  File "/Users/liutianhao/Downloads/team_2_lll/venv/lib/python3.10/site-packages/flask/app.py", line 2525, in wsgi_app
    response = self.full_dispatch_request()
  File "/Users/liutianhao/Downloads/team_2_lll/venv/lib/python3.10/site-packages/flask/app.py", line 1822, in full_dispatch_request
    rv = self.handle_user_exception(e)
  File "/Users/liutianhao/Downloads/team_2_lll/venv/lib/python3.10/site-packages/flask/app.py", line 1820, in full_dispatch_request
    rv = self.dispatch_request()
  File "/Users/liutianhao/Downloads/team_2_lll/venv/lib/python3.10/site-packages/flask/app.py", line 1796, in dispatch_request
    return self.ensure_sync(self.view_functions[rule.endpoint])(**view_args)
  File "/Users/liutianhao/Downloads/team_2_lll/blueprint/profile_blueprint.py", line 53, in index
    return jsonify({'code': 400, 'message': new_product_form.errors.get(e)[0]})
TypeError: 'NoneType' object is not subscriptable
2022-11-22 01:15:43,674 - app - ERROR - Exception on /profile/ [POST]
Traceback (most recent call last):
  File "/Users/liutianhao/Downloads/team_2_lll/venv/lib/python3.10/site-packages/sqlalchemy/engine/base.py", line 1900, in _execute_context
    self.dialect.do_execute(
  File "/Users/liutianhao/Downloads/team_2_lll/venv/lib/python3.10/site-packages/sqlalchemy/engine/default.py", line 736, in do_execute
    cursor.execute(statement, parameters)
sqlite3.OperationalError: database is locked

The above exception was the direct cause of the following exception:

Traceback (most recent call last):
  File "/Users/liutianhao/Downloads/team_2_lll/venv/lib/python3.10/site-packages/flask/app.py", line 2525, in wsgi_app
    response = self.full_dispatch_request()
  File "/Users/liutianhao/Downloads/team_2_lll/venv/lib/python3.10/site-packages/flask/app.py", line 1822, in full_dispatch_request
    rv = self.handle_user_exception(e)
  File "/Users/liutianhao/Downloads/team_2_lll/venv/lib/python3.10/site-packages/flask/app.py", line 1820, in full_dispatch_request
    rv = self.dispatch_request()
  File "/Users/liutianhao/Downloads/team_2_lll/venv/lib/python3.10/site-packages/flask/app.py", line 1796, in dispatch_request
    return self.ensure_sync(self.view_functions[rule.endpoint])(**view_args)
  File "/Users/liutianhao/Downloads/team_2_lll/blueprint/profile_blueprint.py", line 54, in index
    db.session.commit()
  File "<string>", line 2, in commit
  File "/Users/liutianhao/Downloads/team_2_lll/venv/lib/python3.10/site-packages/sqlalchemy/orm/session.py", line 1451, in commit
    self._transaction.commit(_to_root=self.future)
  File "/Users/liutianhao/Downloads/team_2_lll/venv/lib/python3.10/site-packages/sqlalchemy/orm/session.py", line 829, in commit
    self._prepare_impl()
  File "/Users/liutianhao/Downloads/team_2_lll/venv/lib/python3.10/site-packages/sqlalchemy/orm/session.py", line 808, in _prepare_impl
    self.session.flush()
  File "/Users/liutianhao/Downloads/team_2_lll/venv/lib/python3.10/site-packages/sqlalchemy/orm/session.py", line 3386, in flush
    self._flush(objects)
  File "/Users/liutianhao/Downloads/team_2_lll/venv/lib/python3.10/site-packages/sqlalchemy/orm/session.py", line 3525, in _flush
    with util.safe_reraise():
  File "/Users/liutianhao/Downloads/team_2_lll/venv/lib/python3.10/site-packages/sqlalchemy/util/langhelpers.py", line 70, in __exit__
    compat.raise_(
  File "/Users/liutianhao/Downloads/team_2_lll/venv/lib/python3.10/site-packages/sqlalchemy/util/compat.py", line 208, in raise_
    raise exception
  File "/Users/liutianhao/Downloads/team_2_lll/venv/lib/python3.10/site-packages/sqlalchemy/orm/session.py", line 3486, in _flush
    flush_context.execute()
  File "/Users/liutianhao/Downloads/team_2_lll/venv/lib/python3.10/site-packages/sqlalchemy/orm/unitofwork.py", line 456, in execute
    rec.execute(self)
  File "/Users/liutianhao/Downloads/team_2_lll/venv/lib/python3.10/site-packages/sqlalchemy/orm/unitofwork.py", line 630, in execute
    util.preloaded.orm_persistence.save_obj(
  File "/Users/liutianhao/Downloads/team_2_lll/venv/lib/python3.10/site-packages/sqlalchemy/orm/persistence.py", line 245, in save_obj
    _emit_insert_statements(
  File "/Users/liutianhao/Downloads/team_2_lll/venv/lib/python3.10/site-packages/sqlalchemy/orm/persistence.py", line 1238, in _emit_insert_statements
    result = connection._execute_20(
  File "/Users/liutianhao/Downloads/team_2_lll/venv/lib/python3.10/site-packages/sqlalchemy/engine/base.py", line 1705, in _execute_20
    return meth(self, args_10style, kwargs_10style, execution_options)
  File "/Users/liutianhao/Downloads/team_2_lll/venv/lib/python3.10/site-packages/sqlalchemy/sql/elements.py", line 333, in _execute_on_connection
    return connection._execute_clauseelement(
  File "/Users/liutianhao/Downloads/team_2_lll/venv/lib/python3.10/site-packages/sqlalchemy/engine/base.py", line 1572, in _execute_clauseelement
    ret = self._execute_context(
  File "/Users/liutianhao/Downloads/team_2_lll/venv/lib/python3.10/site-packages/sqlalchemy/engine/base.py", line 1943, in _execute_context
    self._handle_dbapi_exception(
  File "/Users/liutianhao/Downloads/team_2_lll/venv/lib/python3.10/site-packages/sqlalchemy/engine/base.py", line 2124, in _handle_dbapi_exception
    util.raise_(
  File "/Users/liutianhao/Downloads/team_2_lll/venv/lib/python3.10/site-packages/sqlalchemy/util/compat.py", line 208, in raise_
    raise exception
  File "/Users/liutianhao/Downloads/team_2_lll/venv/lib/python3.10/site-packages/sqlalchemy/engine/base.py", line 1900, in _execute_context
    self.dialect.do_execute(
  File "/Users/liutianhao/Downloads/team_2_lll/venv/lib/python3.10/site-packages/sqlalchemy/engine/default.py", line 736, in do_execute
    cursor.execute(statement, parameters)
sqlalchemy.exc.OperationalError: (sqlite3.OperationalError) database is locked
[SQL: INSERT INTO product (price, name, description, tag, picture_address, shop_id) VALUES (?, ?, ?, ?, ?, ?)]
[parameters: (11.0, 'ewff', 'kelfwnfewf', 'cloth', 'Xnip2022-11-21_22-53-44.jpg', 1)]
(Background on this error at: https://sqlalche.me/e/14/e3q8)
